<?xml version="1.0" ?>
<!-- =================================================================================== -->
<!-- |    This document was autogenerated by xacro from walker_left_leg.urdf.xacro     | -->
<!-- |    EDITING THIS FILE BY HAND IS NOT RECOMMENDED                                 | -->
<!-- =================================================================================== -->
<robot name="walker" xmlns:xacro="http://www.ros.org/wiki/xacro">
  <material name="gray">
    <color rgba="0.90 0.90 0.90 1.00"/>
  </material>
  <!-- <link name="lfoot_center"/> -->
  <!-- center of the left foot's sole. -->
  <!-- <xacro:create_fixed_joint name="lfoot_center_lfoot_joint" parent="lfoot_center" child="lfoot"/> -->
  <!-- The origin of lfoot_center and lfoot are the same, making the lfoot_center link seem useless, but I've made it since rfoot_center is going to be necessary(because the origin of the link rfoot is not at the center of the right foot's sole, due to the direction of the link chain). -->
  <!-- <link name="lfoot"> -->
  <!-- <xacro:create_mesh name="lfoot"/> -->
  <!-- </link> -->
  <!-- <xacro:create_fixed_joint name="lfoot_lA_joint" parent="lfoot" child="lA" x="-15" z="4"/> -->
  <!-- LEFT LEG -->
  <link name="lA">
    <!-- the offsets are used when "re-using" the left leg meshes for the right leg. It's somewhat confusing. -->
    <visual>
      <geometry>
        <mesh filename="package://walker_description/meshes/lA.stl" scale="0.001 0.001 0.001"/>
      </geometry>
      <material name="gray"/>
      <origin rpy="0 0 0.0" xyz="0.0 0.0 0.0"/>
    </visual>
  </link>
  <joint name="l_ankle_roll" type="revolute">
    <parent link="lA"/>
    <child link="lB"/>
    <origin rpy="0 0 0" xyz="0.019 0.0 0.038"/>
    <axis xyz="1 0 0"/>
    <limit effort="40.0" lower="-0.401425644444" upper="0.401425644444" velocity="1.0"/>
  </joint>
  <link name="lB">
    <!-- the offsets are used when "re-using" the left leg meshes for the right leg. It's somewhat confusing. -->
    <visual>
      <geometry>
        <mesh filename="package://walker_description/meshes/lB.stl" scale="0.001 0.001 0.001"/>
      </geometry>
      <material name="gray"/>
      <origin rpy="0 0 0.0" xyz="0.0 0.0 0.0"/>
    </visual>
  </link>
  <joint name="l_ankle_pitch" type="revolute">
    <parent link="lB"/>
    <child link="lC"/>
    <origin rpy="0 0 0" xyz="-0.01972 0.01954 0.0"/>
    <axis xyz="0 1 0"/>
    <limit effort="40.0" lower="-1.04719733333" upper="1.04719733333" velocity="1.0"/>
  </joint>
  <link name="lC">
    <!-- the offsets are used when "re-using" the left leg meshes for the right leg. It's somewhat confusing. -->
    <visual>
      <geometry>
        <mesh filename="package://walker_description/meshes/lC.stl" scale="0.001 0.001 0.001"/>
      </geometry>
      <material name="gray"/>
      <origin rpy="0 0 0.0" xyz="0.0 0.0 0.0"/>
    </visual>
  </link>
  <joint name="l_knee" type="revolute">
    <parent link="lC"/>
    <child link="lD"/>
    <origin rpy="0 0 0" xyz="0.0 0.0 0.061"/>
    <axis xyz="0 1 0"/>
    <limit effort="40.0" lower="-1.570796" upper="0.0" velocity="1.0"/>
  </joint>
  <link name="lD">
    <!-- the offsets are used when "re-using" the left leg meshes for the right leg. It's somewhat confusing. -->
    <visual>
      <geometry>
        <mesh filename="package://walker_description/meshes/lD.stl" scale="0.001 0.001 0.001"/>
      </geometry>
      <material name="gray"/>
      <origin rpy="0 0 0.0" xyz="0.0 0.0 0.0"/>
    </visual>
  </link>
  <joint name="l_hip_roll" type="revolute">
    <parent link="lD"/>
    <child link="lE"/>
    <origin rpy="0 0 0" xyz="0.019 -0.019 0.058"/>
    <axis xyz="1 0 0"/>
    <limit effort="40.0" lower="-0.401425644444" upper="0.401425644444" velocity="1.0"/>
  </joint>
  <link name="lE">
    <!-- the offsets are used when "re-using" the left leg meshes for the right leg. It's somewhat confusing. -->
    <visual>
      <geometry>
        <mesh filename="package://walker_description/meshes/lB.stl" scale="0.001 0.001 0.001"/>
      </geometry>
      <material name="gray"/>
      <origin rpy="0 0 0.0" xyz="0.0 0.0 0.0"/>
    </visual>
    <!-- lB and lE are the same -->
  </link>
  <link name="lF">
    <!-- the offsets are used when "re-using" the left leg meshes for the right leg. It's somewhat confusing. -->
    <visual>
      <geometry>
        <mesh filename="package://walker_description/meshes/lF.stl" scale="0.001 0.001 0.001"/>
      </geometry>
      <material name="gray"/>
      <origin rpy="0 0 0.0" xyz="0.0 0.0 0.0"/>
    </visual>
  </link>
  <joint name="l_hip_pitch" type="revolute">
    <parent link="lE"/>
    <child link="lF"/>
    <origin rpy="0 0 0" xyz="-0.01972 0.01954 0.0"/>
    <axis xyz="0 1 0"/>
    <limit effort="40.0" lower="-1.04719733333" upper="1.04719733333" velocity="1.0"/>
  </joint>
</robot>

