<?xml version="1.0" ?>
<!-- =================================================================================== -->
<!-- |    This document was autogenerated by xacro from walker.urdf.xacro              | -->
<!-- |    EDITING THIS FILE BY HAND IS NOT RECOMMENDED                                 | -->
<!-- =================================================================================== -->
<robot name="walker" xmlns:xacro="http://www.ros.org/wiki/xacro">
  <material name="gray">
    <color rgba="0.90 0.90 0.90 1.00"/>
  </material>
  <!-- <link name="world"/> -->
  <!-- fix the robot to the world -->
  <!-- <joint name="world_lfoot_joint" type="fixed"> -->
  <!-- <parent link="world"/> -->
  <!-- <child link="lfoot_center"/> -->
  <!-- </joint> -->
  <!-- LEFT FOOT -->
  <link name="lfoot_center"/>
  <!-- center of the left foot's sole. -->
  <!-- <joint name="${name}" type="fixed"> -->
  <joint name="lfoot_center_lfoot_joint" type="revolute">
    <parent link="lfoot_center"/>
    <child link="lfoot"/>
    <axis xyz="1 0 0"/>
    <origin rpy="0 0 0" xyz="0.0 0.0 0.0"/>
  </joint>
  <!-- The origin of lfoot_center and lfoot are the same, making the lfoot_center link seem useless, but I've made it since rfoot_center is going to be necessary(because the origin of the link rfoot is not at the center of the right foot's sole, due to the direction of the link chain). -->
  <link name="lfoot">
    <!-- the offsets are used when "re-using" the left leg meshes for the right leg. It's somewhat confusing. -->
    <visual>
      <geometry>
        <mesh filename="package://walker_description/meshes/lfoot.stl" scale="0.001 0.001 0.001"/>
      </geometry>
      <material name="gray"/>
      <origin rpy="0 0 0.0" xyz="0.0 0.0 0.0"/>
    </visual>
  </link>
  <!-- <joint name="${name}" type="fixed"> -->
  <joint name="lfoot_lA_joint" type="revolute">
    <parent link="lfoot"/>
    <child link="lA"/>
    <axis xyz="1 0 0"/>
    <origin rpy="0 0 0" xyz="-0.015 0.0 0.004"/>
  </joint>
  <!-- LEFT LEG -->
  <link name="lA">
    <!-- the offsets are used when "re-using" the left leg meshes for the right leg. It's somewhat confusing. -->
    <visual>
      <geometry>
        <mesh filename="package://walker_description/meshes/lA.stl" scale="0.001 0.001 0.001"/>
      </geometry>
      <material name="gray"/>
      <origin rpy="0 0 0.0" xyz="0.0 0.0 0.0"/>
    </visual>
  </link>
  <joint name="l_ankle_roll" type="revolute">
    <parent link="lA"/>
    <child link="lB"/>
    <origin rpy="0 0 0" xyz="0.019 0.0 0.038"/>
    <axis xyz="1 0 0"/>
    <limit effort="40.0" lower="-0.401425644444" upper="0.401425644444" velocity="1.0"/>
  </joint>
  <link name="lB">
    <!-- the offsets are used when "re-using" the left leg meshes for the right leg. It's somewhat confusing. -->
    <visual>
      <geometry>
        <mesh filename="package://walker_description/meshes/lB.stl" scale="0.001 0.001 0.001"/>
      </geometry>
      <material name="gray"/>
      <origin rpy="0 0 0.0" xyz="0.0 0.0 0.0"/>
    </visual>
  </link>
  <joint name="l_ankle_pitch" type="revolute">
    <parent link="lB"/>
    <child link="lC"/>
    <origin rpy="0 0 0" xyz="-0.01972 0.01954 0.0"/>
    <axis xyz="0 1 0"/>
    <limit effort="40.0" lower="-1.04719733333" upper="1.04719733333" velocity="1.0"/>
  </joint>
  <link name="lC">
    <!-- the offsets are used when "re-using" the left leg meshes for the right leg. It's somewhat confusing. -->
    <visual>
      <geometry>
        <mesh filename="package://walker_description/meshes/lC.stl" scale="0.001 0.001 0.001"/>
      </geometry>
      <material name="gray"/>
      <origin rpy="0 0 0.0" xyz="0.0 0.0 0.0"/>
    </visual>
  </link>
  <joint name="l_knee" type="revolute">
    <parent link="lC"/>
    <child link="lD"/>
    <origin rpy="0 0 0" xyz="0.0 0.0 0.061"/>
    <axis xyz="0 1 0"/>
    <limit effort="40.0" lower="-1.570796" upper="0.0" velocity="1.0"/>
  </joint>
  <link name="lD">
    <!-- the offsets are used when "re-using" the left leg meshes for the right leg. It's somewhat confusing. -->
    <visual>
      <geometry>
        <mesh filename="package://walker_description/meshes/lD.stl" scale="0.001 0.001 0.001"/>
      </geometry>
      <material name="gray"/>
      <origin rpy="0 0 0.0" xyz="0.0 0.0 0.0"/>
    </visual>
  </link>
  <joint name="l_hip_roll" type="revolute">
    <parent link="lD"/>
    <child link="lE"/>
    <origin rpy="0 0 0" xyz="0.019 -0.019 0.058"/>
    <axis xyz="1 0 0"/>
    <limit effort="40.0" lower="-0.401425644444" upper="0.401425644444" velocity="1.0"/>
  </joint>
  <link name="lE">
    <!-- the offsets are used when "re-using" the left leg meshes for the right leg. It's somewhat confusing. -->
    <visual>
      <geometry>
        <mesh filename="package://walker_description/meshes/lB.stl" scale="0.001 0.001 0.001"/>
      </geometry>
      <material name="gray"/>
      <origin rpy="0 0 0.0" xyz="0.0 0.0 0.0"/>
    </visual>
    <!-- lB and lE are the same -->
  </link>
  <joint name="l_hip_pitch" type="revolute">
    <parent link="lE"/>
    <child link="lF"/>
    <origin rpy="0 0 0" xyz="-0.01972 0.01954 0.0"/>
    <axis xyz="0 1 0"/>
    <limit effort="40.0" lower="-1.04719733333" upper="1.04719733333" velocity="1.0"/>
  </joint>
  <link name="lF">
    <!-- the offsets are used when "re-using" the left leg meshes for the right leg. It's somewhat confusing. -->
    <visual>
      <geometry>
        <mesh filename="package://walker_description/meshes/lF.stl" scale="0.001 0.001 0.001"/>
      </geometry>
      <material name="gray"/>
      <origin rpy="0 0 0.0" xyz="0.0 0.0 0.0"/>
    </visual>
  </link>
  <!-- WAIST -->
  <!-- <joint name="${name}" type="fixed"> -->
  <joint name="lF_waist_joint" type="revolute">
    <parent link="lF"/>
    <child link="waist"/>
    <axis xyz="1 0 0"/>
    <origin rpy="0 0 0" xyz="0.0 -0.019 0.028"/>
  </joint>
  <link name="waist">
    <!-- the offsets are used when "re-using" the left leg meshes for the right leg. It's somewhat confusing. -->
    <visual>
      <geometry>
        <mesh filename="package://walker_description/meshes/waist.stl" scale="0.001 0.001 0.001"/>
      </geometry>
      <material name="gray"/>
      <origin rpy="0 0 0.0" xyz="0.0 0.0 0.0"/>
    </visual>
  </link>
  <!-- <joint name="${name}" type="fixed"> -->
  <joint name="waist_pelvis_joint" type="revolute">
    <parent link="waist"/>
    <child link="pelvis"/>
    <axis xyz="1 0 0"/>
    <origin rpy="0 0 0" xyz="0.0 -0.0235 0.0"/>
  </joint>
  <link name="pelvis"/>
  <!-- pelvis is the "center" of the robot. -->
  <!-- <joint name="${name}" type="fixed"> -->
  <joint name="waist_rF_joint" type="revolute">
    <parent link="waist"/>
    <child link="rF"/>
    <axis xyz="1 0 0"/>
    <origin rpy="0 0 0" xyz="0.0 -0.047 0.0"/>
  </joint>
  <!-- RIGHT LEG -->
  <link name="rF">
    <!-- the offsets are used when "re-using" the left leg meshes for the right leg. It's somewhat confusing. -->
    <visual>
      <geometry>
        <mesh filename="package://walker_description/meshes/lF.stl" scale="0.001 0.001 0.001"/>
      </geometry>
      <material name="gray"/>
      <origin rpy="0 0 3.141592" xyz="0.0 -0.019 -0.028"/>
    </visual>
  </link>
  <joint name="r_hip_pitch" type="revolute">
    <parent link="rF"/>
    <child link="rE"/>
    <origin rpy="0 0 0" xyz="0.0 -0.019 -0.028"/>
    <axis xyz="0 1 0"/>
    <limit effort="40.0" lower="-1.04719733333" upper="1.04719733333" velocity="1.0"/>
  </joint>
  <link name="rE">
    <!-- the offsets are used when "re-using" the left leg meshes for the right leg. It's somewhat confusing. -->
    <visual>
      <geometry>
        <mesh filename="package://walker_description/meshes/lB.stl" scale="0.001 0.001 0.001"/>
      </geometry>
      <material name="gray"/>
      <origin rpy="0 0 3.141592" xyz="-0.01972 0.01954 0.0"/>
    </visual>
    <!-- re-using the meshes from the right leg. It's a bit confusing to set the origin parameters, and I've done it through trial and error lol -->
  </link>
  <joint name="r_hip_roll" type="revolute">
    <parent link="rE"/>
    <child link="rD"/>
    <origin rpy="0 0 0" xyz="0.01972 0.01954 0.0"/>
    <axis xyz="1 0 0"/>
    <limit effort="40.0" lower="-0.401425644444" upper="0.401425644444" velocity="1.0"/>
  </joint>
  <link name="rD">
    <!-- the offsets are used when "re-using" the left leg meshes for the right leg. It's somewhat confusing. -->
    <visual>
      <geometry>
        <mesh filename="package://walker_description/meshes/lD.stl" scale="0.001 0.001 0.001"/>
      </geometry>
      <material name="gray"/>
      <origin rpy="0 0 3.141592" xyz="-0.019 -0.019 -0.058"/>
    </visual>
  </link>
  <joint name="r_knee" type="revolute">
    <parent link="rD"/>
    <child link="rC"/>
    <origin rpy="0 0 0" xyz="-0.019 -0.019 -0.058"/>
    <axis xyz="0 1 0"/>
    <limit effort="40.0" lower="0.0" upper="1.570796" velocity="1.0"/>
  </joint>
  <link name="rC">
    <!-- the offsets are used when "re-using" the left leg meshes for the right leg. It's somewhat confusing. -->
    <visual>
      <geometry>
        <mesh filename="package://walker_description/meshes/lC.stl" scale="0.001 0.001 0.001"/>
      </geometry>
      <material name="gray"/>
      <origin rpy="0 0 3.141592" xyz="0.0 0.0 -0.061"/>
    </visual>
  </link>
  <joint name="r_ankle_pitch" type="revolute">
    <parent link="rC"/>
    <child link="rB"/>
    <origin rpy="0 0 0" xyz="0.0 0.0 -0.061"/>
    <axis xyz="0 1 0"/>
    <limit effort="40.0" lower="-1.04719733333" upper="1.04719733333" velocity="1.0"/>
  </joint>
  <link name="rB">
    <!-- the offsets are used when "re-using" the left leg meshes for the right leg. It's somewhat confusing. -->
    <visual>
      <geometry>
        <mesh filename="package://walker_description/meshes/lB.stl" scale="0.001 0.001 0.001"/>
      </geometry>
      <material name="gray"/>
      <origin rpy="0 0 3.141592" xyz="-0.01972 0.01954 0.0"/>
    </visual>
  </link>
  <joint name="r_ankle_roll" type="revolute">
    <parent link="rB"/>
    <child link="rA"/>
    <origin rpy="0 0 0" xyz="0.01972 0.01954 0.0"/>
    <axis xyz="1 0 0"/>
    <limit effort="40.0" lower="-0.401425644444" upper="0.401425644444" velocity="1.0"/>
  </joint>
  <link name="rA">
    <!-- the offsets are used when "re-using" the left leg meshes for the right leg. It's somewhat confusing. -->
    <visual>
      <geometry>
        <mesh filename="package://walker_description/meshes/lA.stl" scale="0.001 0.001 0.001"/>
      </geometry>
      <material name="gray"/>
      <origin rpy="0 0 3.141592" xyz="-0.019 0.0 -0.038"/>
    </visual>
  </link>
  <!-- RIGHT FOOT -->
  <!-- <joint name="${name}" type="fixed"> -->
  <joint name="rA_rfoot_joint" type="revolute">
    <parent link="rA"/>
    <child link="rfoot"/>
    <axis xyz="1 0 0"/>
    <origin rpy="0 0 0" xyz="-0.019 0.0 -0.038"/>
  </joint>
  <link name="rfoot">
    <!-- the offsets are used when "re-using" the left leg meshes for the right leg. It's somewhat confusing. -->
    <visual>
      <geometry>
        <mesh filename="package://walker_description/meshes/lfoot.stl" scale="0.001 0.001 0.001"/>
      </geometry>
      <material name="gray"/>
      <origin rpy="0 0 0.0" xyz="0.015 0.0 -0.004"/>
    </visual>
  </link>
  <!-- <joint name="${name}" type="fixed"> -->
  <joint name="rfoot_rfoot_center_joint" type="revolute">
    <parent link="rfoot"/>
    <child link="rfoot_center"/>
    <axis xyz="1 0 0"/>
    <origin rpy="0 0 0" xyz="0.015 0.0 -0.004"/>
  </joint>
  <link name="rfoot_center"/>
</robot>

